Applyinh this command : python3 manage.py makemigrations
the Error list is following.

Traceback (most recent call last):
  File "/home/tx/.local/lib/python3.5/site-packages/django/db/backends/utils.py", line 84, in _execute
    return self.cursor.execute(sql, params)
  File "/home/tx/.local/lib/python3.5/site-packages/django/db/backends/sqlite3/base.py", line 383, in execute
    return Database.Cursor.execute(self, query, params)
sqlite3.OperationalError: no such table: myapp_frame

The above exception was the direct cause of the following exception:

Traceback (most recent call last):
  File "manage.py", line 22, in <module>
    main()
  File "manage.py", line 18, in main
    execute_from_command_line(sys.argv)
  File "/home/tx/.local/lib/python3.5/site-packages/django/core/management/__init__.py", line 381, in execute_from_command_line
    utility.execute()
  File "/home/tx/.local/lib/python3.5/site-packages/django/core/management/__init__.py", line 375, in execute
    self.fetch_command(subcommand).run_from_argv(self.argv)
  File "/home/tx/.local/lib/python3.5/site-packages/django/core/management/base.py", line 323, in run_from_argv
    self.execute(*args, **cmd_options)
  File "/home/tx/.local/lib/python3.5/site-packages/django/core/management/base.py", line 361, in execute
    self.check()
  File "/home/tx/.local/lib/python3.5/site-packages/django/core/management/base.py", line 390, in check
    include_deployment_checks=include_deployment_checks,
  File "/home/tx/.local/lib/python3.5/site-packages/django/core/management/base.py", line 377, in _run_checks
    return checks.run_checks(**kwargs)
  File "/home/tx/.local/lib/python3.5/site-packages/django/core/checks/registry.py", line 72, in run_checks
    new_errors = check(app_configs=app_configs)
  File "/home/tx/.local/lib/python3.5/site-packages/django/core/checks/urls.py", line 40, in check_url_namespaces_unique
    all_namespaces = _load_all_namespaces(resolver)
  File "/home/tx/.local/lib/python3.5/site-packages/django/core/checks/urls.py", line 57, in _load_all_namespaces
    url_patterns = getattr(resolver, 'url_patterns', [])
  File "/home/tx/.local/lib/python3.5/site-packages/django/utils/functional.py", line 80, in __get__
    res = instance.__dict__[self.name] = self.func(instance)
  File "/home/tx/.local/lib/python3.5/site-packages/django/urls/resolvers.py", line 584, in url_patterns
    patterns = getattr(self.urlconf_module, "urlpatterns", self.urlconf_module)
  File "/home/tx/.local/lib/python3.5/site-packages/django/utils/functional.py", line 80, in __get__
    res = instance.__dict__[self.name] = self.func(instance)
  File "/home/tx/.local/lib/python3.5/site-packages/django/urls/resolvers.py", line 577, in urlconf_module
    return import_module(self.urlconf_name)
  File "/usr/lib/python3.5/importlib/__init__.py", line 126, in import_module
    return _bootstrap._gcd_import(name[level:], package, level)
  File "<frozen importlib._bootstrap>", line 986, in _gcd_import
  File "<frozen importlib._bootstrap>", line 969, in _find_and_load
  File "<frozen importlib._bootstrap>", line 958, in _find_and_load_unlocked
  File "<frozen importlib._bootstrap>", line 673, in _load_unlocked
  File "<frozen importlib._bootstrap_external>", line 665, in exec_module
  File "<frozen importlib._bootstrap>", line 222, in _call_with_frames_removed
  File "/home/tx/ib_server/myserver/urls.py", line 19, in <module>
    urlpatterns = [path('myapp/', include('myapp.urls')), path('admin/', admin.site.urls),]
  File "/home/tx/.local/lib/python3.5/site-packages/django/urls/conf.py", line 34, in include
    urlconf_module = import_module(urlconf_module)
  File "/usr/lib/python3.5/importlib/__init__.py", line 126, in import_module
    return _bootstrap._gcd_import(name[level:], package, level)
  File "<frozen importlib._bootstrap>", line 986, in _gcd_import
  File "<frozen importlib._bootstrap>", line 969, in _find_and_load
  File "<frozen importlib._bootstrap>", line 958, in _find_and_load_unlocked
  File "<frozen importlib._bootstrap>", line 673, in _load_unlocked
  File "<frozen importlib._bootstrap_external>", line 665, in exec_module
  File "<frozen importlib._bootstrap>", line 222, in _call_with_frames_removed
  File "/home/tx/ib_server/myapp/urls.py", line 3, in <module>
    from . import views
  File "/home/tx/ib_server/myapp/views.py", line 10, in <module>
    request_handler = RequestHandler(Frame)
  File "/home/tx/ib_server/myapp/RequestHandler.py", line 15, in __init__
    self.distincts = [[z[f] for z in Frame.objects.values(f).distinct()] for f in self.field_name]
  File "/home/tx/ib_server/myapp/RequestHandler.py", line 15, in <listcomp>
    self.distincts = [[z[f] for z in Frame.objects.values(f).distinct()] for f in self.field_name]
  File "/home/tx/.local/lib/python3.5/site-packages/django/db/models/query.py", line 274, in __iter__
    self._fetch_all()
  File "/home/tx/.local/lib/python3.5/site-packages/django/db/models/query.py", line 1242, in _fetch_all
    self._result_cache = list(self._iterable_class(self))
  File "/home/tx/.local/lib/python3.5/site-packages/django/db/models/query.py", line 113, in __iter__
    for row in compiler.results_iter(chunked_fetch=self.chunked_fetch, chunk_size=self.chunk_size):
  File "/home/tx/.local/lib/python3.5/site-packages/django/db/models/sql/compiler.py", line 1052, in results_iter
    results = self.execute_sql(MULTI, chunked_fetch=chunked_fetch, chunk_size=chunk_size)
  File "/home/tx/.local/lib/python3.5/site-packages/django/db/models/sql/compiler.py", line 1100, in execute_sql
    cursor.execute(sql, params)
  File "/home/tx/.local/lib/python3.5/site-packages/django/db/backends/utils.py", line 99, in execute
    return super().execute(sql, params)
  File "/home/tx/.local/lib/python3.5/site-packages/django/db/backends/utils.py", line 67, in execute
    return self._execute_with_wrappers(sql, params, many=False, executor=self._execute)
  File "/home/tx/.local/lib/python3.5/site-packages/django/db/backends/utils.py", line 76, in _execute_with_wrappers
    return executor(sql, params, many, context)
  File "/home/tx/.local/lib/python3.5/site-packages/django/db/backends/utils.py", line 84, in _execute
    return self.cursor.execute(sql, params)
  File "/home/tx/.local/lib/python3.5/site-packages/django/db/utils.py", line 89, in __exit__
    raise dj_exc_value.with_traceback(traceback) from exc_value
  File "/home/tx/.local/lib/python3.5/site-packages/django/db/backends/utils.py", line 84, in _execute
    return self.cursor.execute(sql, params)
  File "/home/tx/.local/lib/python3.5/site-packages/django/db/backends/sqlite3/base.py", line 383, in execute
    return Database.Cursor.execute(self, query, params)
django.db.utils.OperationalError: no such table: myapp_frame
